Traceback (most recent call last):
  File "C:\Users\wilso\miniconda3\envs\sysidentpy\lib\site-packages\jupyter_cache\executors\utils.py", line 51, in single_nb_execution
    executenb(
  File "C:\Users\wilso\miniconda3\envs\sysidentpy\lib\site-packages\nbclient\client.py", line 1117, in execute
    return NotebookClient(nb=nb, resources=resources, km=km, **kwargs).execute()
  File "C:\Users\wilso\miniconda3\envs\sysidentpy\lib\site-packages\nbclient\util.py", line 78, in wrapped
    return just_run(coro(*args, **kwargs))
  File "C:\Users\wilso\miniconda3\envs\sysidentpy\lib\site-packages\nbclient\util.py", line 57, in just_run
    return loop.run_until_complete(coro)
  File "C:\Users\wilso\miniconda3\envs\sysidentpy\lib\asyncio\base_events.py", line 616, in run_until_complete
    return future.result()
  File "C:\Users\wilso\miniconda3\envs\sysidentpy\lib\site-packages\nbclient\client.py", line 558, in async_execute
    await self.async_execute_cell(
  File "C:\Users\wilso\miniconda3\envs\sysidentpy\lib\site-packages\nbclient\client.py", line 862, in async_execute_cell
    self._check_raise_for_error(cell, exec_reply)
  File "C:\Users\wilso\miniconda3\envs\sysidentpy\lib\site-packages\nbclient\client.py", line 765, in _check_raise_for_error
    raise CellExecutionError.from_cell_and_msg(cell, exec_reply_content)
nbclient.exceptions.CellExecutionError: An error occurred while executing the following cell:
------------------
import seaborn as sns
import matplotlib.pyplot as plt

parameters = np.zeros([3, 50])

for i in range(50):
    x_train, x_valid, y_train, y_valid = get_siso_data(n=3000,
                                                       colored_noise=True,
                                                       train_percentage=90)
    
    model.fit(x_train, y_train)
    parameters[:, i] = list(model.theta)

sns.set()
pal = sns.cubehelix_palette(3, rot=-.5, dark=.3)

ax = sns.kdeplot(parameters.T[:, 0])
ax = sns.kdeplot(parameters.T[:, 1])
ax = sns.kdeplot(parameters.T[:, 2])
# plotting a vertical line where the real values must lie
ax = plt.axvline(x=0.1, c='k')
ax = plt.axvline(x=0.2, c='k')
ax = plt.axvline(x=0.9, c='k')
------------------

[1;31m---------------------------------------------------------------------------[0m
[1;31mModuleNotFoundError[0m                       Traceback (most recent call last)
[1;32m~\AppData\Local\Temp/ipykernel_9208/3592060221.py[0m in [0;36m<module>[1;34m[0m
[1;32m----> 1[1;33m [1;32mimport[0m [0mseaborn[0m [1;32mas[0m [0msns[0m[1;33m[0m[1;33m[0m[0m
[0m[0;32m      2[0m [1;32mimport[0m [0mmatplotlib[0m[1;33m.[0m[0mpyplot[0m [1;32mas[0m [0mplt[0m[1;33m[0m[1;33m[0m[0m
[0;32m      3[0m [1;33m[0m[0m
[0;32m      4[0m [0mparameters[0m [1;33m=[0m [0mnp[0m[1;33m.[0m[0mzeros[0m[1;33m([0m[1;33m[[0m[1;36m3[0m[1;33m,[0m [1;36m50[0m[1;33m][0m[1;33m)[0m[1;33m[0m[1;33m[0m[0m
[0;32m      5[0m [1;33m[0m[0m

[1;31mModuleNotFoundError[0m: No module named 'seaborn'
ModuleNotFoundError: No module named 'seaborn'

